Workbook
Name abmax: 'Data and Kn'!$K$96
Name abo: 'Data and Kn'!$C$33
Name ae_1: Burnrate!$E$52
Name aexit: Performance!$C$8
Name alpha: 'Nozzle Design'!$Y$9
Name am_0: Burnrate!$J$28
Name am_1: Burnrate!$J$52
Name am_3: Burnrate!$J$58
Name am_4: Burnrate!$J$64
Name an_0: Burnrate!$K$28
Name an_4: Burnrate!$K$64
Name astarf: Pressure!$I$862
Name at: 'Data and Kn'!$C$36
Name atfinal: Performance!$E$862
Name beta: 'Nozzle Design'!$Y$10
Name chpressures: 'Data and Kn'!$AA$17:$AA$36
Name ci: 'Data and Kn'!$Y$20
Name cstar: Pressure!$C$17
Name dc: 'Data and Kn'!$C$10
Name dcplot: 'Nozzle Design'!$C$9
Name deltap: Pressure!$AA$909
Name deltat: Pressure!$D$864
Name deltax: 'Data and Kn'!$C$96
Name dio: 'Data and Kn'!$C$17
Name do: 'Data and Kn'!$C$16
Name dto: 'Data and Kn'!$C$37
Name ei: 'Data and Kn'!$Y$21
Name erate: 'Data and Kn'!$C$39
Name etac: Pressure!$C$13
Name etanoz: Performance!$C$4
Name exprat: Performance!$C$5
Name expratfinal: Performance!$F$862
Name fmax: Performance!$C$16
Name fueltype: 'Data and Kn'!$X$31
Name gstar: Pressure!$C$18
Name itot: Performance!$C$17
Name itsum: Performance!$L$911
Name k: Pressure!$C$12
Name k2ph: Performance!$C$3
Name kn: 'Data and Kn'!$C$35
Name kndxbn_: Burnrate!$G$8:$K$12
Name knotherbn_: Burnrate!$G$52:$K$56
Name knrange: 'Data and Kn'!$M$45:$M$95
Name knsbcobn_: Burnrate!$G$28:$K$28
Name knselecttab: 'Data and Kn'!$AN$32:$AO$39
Name knsobn_: Burnrate!$G$19:$K$23
Name knsubn_: Burnrate!$G$33:$K$33
Name ks_dx: 'Propellant data'!$F$10
Name ks_er: 'Propellant data'!$I$10
Name ks_fr: 'Propellant data'!$K$10
Name ks_mn: 'Propellant data'!$J$10
Name ks_ot: 'Propellant data'!$L$10
Name ks_so: 'Propellant data'!$G$10
Name ks_su: 'Propellant data'!$H$10
Name kv: Pressure!$C$19
Name lc: 'Data and Kn'!$C$11
Name lgo: 'Data and Kn'!$C$23
Name lo: 'Data and Kn'!$C$18
Name m: Pressure!$C$10
Name m_dx: 'Propellant data'!$F$11

Sheet Intro
B4: SRM 2023.XLS | D4: Written by: | E4: Richard A.Nakka
B5: Solid Rocket Motor Performance | D5: Version: | E5: 2023 (for free distribution). Supercedes SRM_2014.XLS version 1.1 (2014)
D6: Date: | E6: 45008
B8: Instructions for use: Enter required data in the blue-outlined cells (with blue text)
B9: Note that some data cells have drop-down lists
B10: Then click on the Solve buttons (1-3)
B13: Introduction
B15: Changes incorporated into SRM 2023 version
B17: KNPSB and KNFR have been added to the choice of propellants. All propellant properties have been
B18: tweaked based on revised two-phase flow analysis. The value of "k" is corrected to a single value. The
B19: overall effect of these updated property values is a small reduction in predicted performance (thrust, total
B20: impulse & specific impulse) compared to SRM_2014. Motor performance up to "V" class is now supported.
B23: This spreadsheet was created in order to predict the performance of a Solid Rocket
B24: Motor (SRM). Although there are many factors which make a precise prediction
B25: of actual performance difficult, it was felt that a reasonably close approximation
... B87: website: www.nakka-rocketry.net

Sheet Data and Kn
B4: Basic Data and Kn Calculation
B6: Title: | C6: Example Rocket Motor (L-Class)
C7: utilizing KNDX propellant.
C8: Hint! To directly convert inches to mm, simply type =25.4*number where number is dimension in inches.
B9: Motor chamber:
B10: Dc | C10: 75 | D10: mm | E10: Chamber diameter (inside)
B11: Lc | C11: 470 | D11: mm | E11: Chamber length (inside)
B12: Vc | C12: =PI()/4*dc^2*lc -> 2076396.4 | D12: mm3 | E12: Chamber volume (empty)
B13: Propellant grain:
B14: Propellant type | C14: KNDX | D14: select | E14: See Note [1] below
A16: =IF(do>dc,"Invalid","") | B16: Do | C16: 69 | D16: mm | E16: Outer diameter (initial)
B17: do | C17: 20 | D17: mm | E17: Core diameter (initial) | X17: KNDX | Y17: Exposed | AA17: 9 MPa | AB17: 9 | AD17: Kn versus Pressure for propellants. | AH17: Kn = a + b*P + c*P2 + d*P3 + e*P4 + f*P5 + g*P6
B18: Lo | C18: 115 | D18: mm | E18: Segment length (initial) | X18: KNSB fine | Y18: Inhibited | AA18: 8.5 MPa | AB18: 8.5 | AH18: where units of P is "MPa"
A19: =IF(lo>lc/n,"Invalid","") | B19: N | C19: 4 | E19: Number of segments | X19: KNSB coarse | Y19: =IF(C20="Inhibited",0,1) -> 0 | AA19: 8 MPa | AB19: 8 | AG19: Polynomial coefficients for Least Squares Fit of Kn as fcn of Pressure data
B20: Outer surface: | C20: Inhibited | D20: select | X20: KNSU | Y20: =IF(C21="Inhibited",0,1) -> 1 | AA20: 7.5 MPa | AB20: 7.5 | AE20: Kn init | AF20: order | AG20: a | AH20: b | AI20: c | AJ20: d | AK20: e | AL20: f | AM20: g | AN20: calc Kn | AO20: Range incr
B21: Core surface: | C21: Exposed | D21: select | X21: KNER coarse | Y21: =IF(C22="Inhibited",0,1) -> 1 | AA21: 7 MPa | AB21: 7 | AD21: KNDX | AF21: 3 | AG21: 43.5 | AH21: 0.24168 | AI21: 50.48413 | AJ21: -9.91148 | AN21: =AG21+AH21*$AE$32+AI21*$AE$32^2+AJ21*$AE$32^3+AK21*$AE$32^4+AL21*$AE$32^5+AM21*$AE$32^6 -> -379.42099 | AO21: 150-400 psi
A22: =IF(osi>1,"Error","") | B22: Ends surface: | C22: Exposed | D22: select | X22: KNMN coarse | AA22: 6.5 MPa | AB22: 6.5 | AF22: 2 | AG22: 163.8 | AH22: 22.22414 | AI22: -0.224 | AN22: =AG22+AH22*$AE$32+AI22*$AE$32^2+AJ22*$AE$32^3+AK22*$AE$32^4+AL22*$AE$32^5+AM22*$AE$32^6 -> 293.08606 | AO22: 450-850 psi
A23: =IF(ci>1,"Error","") | B23: Lgo | C23: =n*lo -> 460 | D23: mm | E23: Grain length (initial) | X23: KNPSB | AA23: 6 MPa | AB23: 6 | AF23: 4 | AG23: 5095 | AH23: -2460.426 | AI23: 453.4805 | AJ23: -35.53239 | AK23: 1.01745 | AN23: =AG23+AH23*$AE$32+AI23*$AE$32^2+AJ23*$AE$32^3+AK23*$AE$32^4+AL23*$AE$32^5+AM23*$AE$32^6 -> 307.39787 | AO23: 900-1300 psi
A24: =IF(ei>1,"Error","") | B24: Vg | C24: =PI()/4*(do^2-dio^2)*lgo -> 1575555.8 | D24: mm3 | E24: Grain volume (initial) | X24: KNFR | AA24: 5.5 MPa | AB24: 5.5 | AD24: KNSB fine | AF24: 5 | AG24: 34.5 | AH24: -10.975 | AI24: 69.667 | AJ24: -19.664 | AK24: 2.1478 | AL24: -0.081463 | AN24: =AG24+AH24*$AE$32+AI24*$AE$32^2+AJ24*$AE$32^3+AK24*$AE$32^4+AL24*$AE$32^5+AM24*$AE$32^6 -> 385.49498 | AO24: 0-1300 psi
B25: V l | C25: =vg/vc -> 0.75879338 | E25: Volumetric loading fraction | AA25: 5 MPa | AB25: 5 | AD25: KNSB coarse | AF25: 2 | AG25: 38 | AH25: 92.391 | AI25: -2.0438 | AN25: =AG25+AH25*$AE$32+AI25*$AE$32^2+AJ25*$AE$32^3+AK25*$AE$32^4+AL25*$AE$32^5+AM25*$AE$32^6 -> 532.62923 | AO25: 0-1300 psi
B26: r' grain | C26: =IF(fueltype=1,rhopdex,IF(fueltype=2,rhopsorb,IF(fueltype=3,rhopsorb,IF(fueltype=4,rhopsu,IF(fueltype=5,rhoper,IF(fueltype=6,rhopmn,IF(fueltype=7,rhopot,rhopfr))))))) -> 1.879 | D26: g/cm3 | E26: Grain ideal density | AA26: 4.5 MPa | AB26: 4.5 | AD26: KNSU | AF26: 2 | AG26: 32.9539 | AH26: 44.1079 | AI26: -1.10248 | AN26: =AG26+AH26*$AE$32+AI26*$AE$32^2+AJ26*$AE$32^3+AK26*$AE$32^4+AL26*$AE$32^5+AM26*$AE$32^6 -> 264.21092 | AO26: 0-1300 psi
C27: 0.95 | E27: Density ratio (actual/ideal) | AA27: 4 MPa | AB27: 4 | AD27: KNER coarse | AF27: 5 | AG27: 50.410353 | AH27: 211.19402 | AI27: -47.797596 | AJ27: 8.779018 | AK27: -0.830282 | AL27: 0.030519 | AN27: =AG27+AH27*$AE$32+AI27*$AE$32^2+AJ27*$AE$32^3+AK27*$AE$32^4+AL27*$AE$32^5+AM27*$AE$32^6 -> 667.85812 | AO27: 0-1300 psi
B28: r grain | C28: =rhorat*rhopgraini -> 1.78505 | D28: g/cm3 | E28: Grain actual density | AA28: 3.5 MPa | AB28: 3.5 | AD28: KNMN coarse | AF28: 2 | AG28: 38 | AH28: 92.391 | AI28: -2.0438 | AN28: =AG28+AH28*$AE$32+AI28*$AE$32^2+AJ28*$AE$32^3+AK28*$AE$32^4+AL28*$AE$32^5+AM28*$AE$32^6 -> 532.62923 | AO28: 0-1300 psi
B29: m grain | C29: =rhopgrain*vg/1000/1000 -> 2.812446 | D29: kg. | E29: Grain mass (initial) | AA29: 3 MPa | AB29: 3 | AD29: KNPSB | AF29: 3 | AG29: 54.53 | AH29: 33.652 | AI29: -3.4185 | AJ29: 0.1545 | AN29: =AG29+AH29*$AE$32+AI29*$AE$32^2+AJ29*$AE$32^3+AK29*$AE$32^4+AL29*$AE$32^5+AM29*$AE$32^6 -> 168.63686 | AO29: 0-1300 psi
B30: Abeo | C30: =n*2*ei*PI()/4*(do^2-dio^2) -> 27400.971 | D30: mm2 | E30: End burning area (initial) | AA30: 2.5 MPa | AB30: 2.5 | AD30: KNFR | AF30: 2 | AG30: 39.748 | AH30: 51.618 | AI30: -0.9264 | AN30: =AG30+AH30*$AE$32+AI30*$AE$32^2+AJ30*$AE$32^3+AK30*$AE$32^4+AL30*$AE$32^5+AM30*$AE$32^6 -> 324.38947 | AO30: 0-1300 psi
B31: Abco | C31: =n*ci*PI()*dio*lo -> 28902.652 | D31: mm2 | E31: Core burning area (initial) | X31: =IF(C14="KNDX",1,IF(C14="KNSB fine",2,IF(C14="KNSB coarse",3,IF(C14="KNSU",4,IF(C14="KNER coarse",5,IF(C14="KNMN coarse",6,IF(C14="KNPSB",7,8))))))) -> 1 | AA31: 2 MPa | AB31: 2 | AD31: Ptarget: | AN31: fueltype | AO31: Kn
B32: Abso | C32: =n*osi*PI()*do*lo -> 0 | D32: mm2 | E32: Outer surface burning area (initial) | AA32: 1.5 MPa | AB32: 1.5 | AD32: =C34 -> 900 psi | AE32: =VLOOKUP(AD32,AA17:AB57,2,FALSE) -> 6.2055 | AF32: MPa | AN32: 1 | AO32: =IF(pmselect<3,AN21,IF(pmselect<6,AN22,AN23)) -> 307.39787
B33: Abo | C33: =SUM(C30:C32) -> 56303.624 | D33: mm2 | E33: Total burning area (initial) | K33: =C96 -> 0 | AA33: 1 MPa | AB33: 1 | AN33: 2 | AO33: =AN24 -> 385.49498
B34: Target MEOP: | C34: 900 psi | D34: select | E34: Maximum chamber pressure (target) | AA34: 1300 psi | AB34: =1300*6895/1000000 -> 8.9635 | AN34: 3 | AO34: =AN25 -> 532.62923
B35: Kn max: | C35: =VLOOKUP(fueltype,knselecttab,2,FALSE) -> 307.39787 | E35: Ratio of Burning area / throat area (max) | I35: Kn max | J35: =MAX(knrange) -> 307.39787 | AA35: 1250 psi | AB35: =1250*6895/1000000 -> 8.61875 | AN35: 4 | AO35: =AN26 -> 264.21092
B36: Nozzle: Ato | C36: =abmax/kn -> 221.47276 | D36: mm2 | E36: Throat cross-section area (initial) | I36: Kn min | J36: =MIN(knrange) -> 254.2237 | AA36: 1200 psi | AB36: =1200*6895/1000000 -> 8.274 | AN36: 5 | AO36: =AN27 -> 667.85812
B37: Dto | C37: =SQRT(4*at/PI()) -> 16.792494 | D37: mm | E37: Throat diameter (initial) | I37: Kn avg | J37: =AVERAGE(knrange) -> 289.68593 | AA37: 1150 psi | AB37: =1150*6895/1000000 -> 7.92925 | AN37: 6 | AO37: =AN28 -> 532.62923
AA38: 1100 psi | AB38: =1100*6895/1000000 -> 7.5845 | AN38: 7 | AO38: =AN29 -> 168.63686
B39: e | C39: 0 | D39: mm | E39: Nozzle erosion | AA39: 1050 psi | AB39: =1050*6895/1000000 -> 7.23975 | AN39: 8 | AO39: =AN30 -> 324.38947
B40: Dtf | C40: =SQRT(4*at/PI())+erate -> 16.792494 | D40: mm | E40: Throat diameter (final) | AA40: 1000 psi | AB40: =1000*6895/1000000 -> 6.895
AA41: 950 psi | AB41: =950*6895/1000000 -> 6.55025
B42: xinc | C42: 0.49 | D42: mm | E42: Kn Table | G42: =IF(twebfinal>0.1,"Error code 01--convergence failure","") | AA42: 900 psi | AB42: =900*6895/1000000 -> 6.2055
B43: Interval | C43: x | D43: d | E43: D | F43: L | G43: tweb | H43: Abe | I43: Abc | J43: Abs | K43: Ab total | L43: At | M43: Kn | AA43: 850 psi | AB43: =850*6895/1000000 -> 5.86075
C44: mm | D44: mm | E44: mm | F44: mm | G44: mm | H44: mm2 | I44: mm2 | J44: mm2 | K44: mm2 | L44: mm2 | AA44: 800 psi | AB44: =800*6895/1000000 -> 5.516
B45: 0 | C45: 0 | D45: =dio+ci*(2*C45) -> 20 | E45: =do-osi*(2*C45) -> 69 | F45: =lgo-ei*(2*n*C45) -> 460 | G45: =(E45-D45)/2 -> 24.5 | H45: =ei*2*n*PI()/4*(E45^2-D45^2) -> 27400.971 | I45: =ci*PI()*D45*F45 -> 28902.652 | J45: =osi*PI()*E45*F45 -> 0 | K45: =SUM(H45:J45) -> 56303.624 | L45: =PI()/4*(dto+erate*(two-G45)/two)^2 -> 221.47276 | M45: =K45/L45 -> 254.2237 | AA45: 750 psi | AB45: =750*6895/1000000 -> 5.17125
...

Sheet Pressure
B5: Rocket Motor chamber pressure
B9: R' | C9: 8314 | D9: J/mol-K | E9: Universal gas constant
B10: M | C10: =IF(fueltype=1,m_dx,IF(fueltype=2,m_so,IF(fueltype=3,m_so,IF(fueltype=4,m_su,IF(fueltype=5,m_er,IF(fueltype=6,m_mn,IF(fueltype=7,m_ot,m_fr))))))) -> 42.42 | D10: kg/kmol | E10: Effective molecular wt.of products
B11: R | C11: =runiv/m -> 195.99246 | D11: J/kg-K | E11: Specific gas constant
B12: k | C12: =IF(fueltype=1,ks_dx,IF(fueltype=2,ks_so,IF(fueltype=3,ks_so,IF(fueltype=4,ks_su,IF(fueltype=5,ks_er,IF(fueltype=6,ks_mn,IF(fueltype=7,ks_ot,ks_fr))))))) -> 1.1308 | E12: Ratio of specific heats, mixture
B13: hc | C13: 0.95 | E13: Combustion efficiency
B14: To | C14: =IF(fueltype=1,to_dx,IF(fueltype=2,to_so,IF(fueltype=3,to_so,IF(fueltype=4,to_su,IF(fueltype=5,to_er,IF(fueltype=6,to_mn,IF(fueltype=7,to_ot,to_fr))))))) -> 1710 | D14: K | E14: Ideal combustion temperature
B15: To act | C15: =etac*tothe -> 1624.5 | D15: K | E15: Actual chamber temperature
B16: Patm | C16: 0.101 | D16: MPa | E16: Ambient pressure
B17: c* | C17: =SQRT(rat*to/k*((k+1)/2)^((k+1)/(k-1))) -> 888.96501 | D17: m/s | E17: Characteristic exhaust velocity
B18: G* | C18: 6 | E18: Propellant erosive burning area ratio threshold | J18: Pmax = | K18: =pmax -> 6.3037269 | L18: MPa | O18: Pmax = | P18: =pmax/0.006895 -> 914.24611 | Q18: psi
B19: kv | C19: 0 | E19: Propellant erosive burning velocity coefficient | J19: t burn = | K19: =tbout -> 1.9422242 | L19: s. | O19: t burn = | P19: =tbout -> 1.9422242 | Q19: s.
J20: t thrust = | K20: =tthr -> 2.0252514 | L20: s. | O20: t thrust = | P20: =tthr -> 2.0252514 | Q20: s.
W22: Pburst = | X22: 0 | Y22: MPa. | AA22: Pmax= | AB22: =MAX(AC28:AC910) -> 6.3037269 | AC22: MPa
G23: =D862 -> 1.8189894e-12 | J23: 0.0017665369 | K23: <=Note: In case of non-convergence to zero, change value in this cell to a small "seed" value (e.g. .01)
B24: xinc | C24: 0.029376499 | D24: mm
B25: Interval | C25: xi | D25: tweb | E25: d | F25: D | G25: L | H25: At | I25: A* | J25: ADUCT | K25: ADUCT /At | L25: G | M25: Po | N25: a | O25: n | P25: r | Q25: t | R25: V GRAIN | S25: V GRAIN | T25: V FREE | U25: m GRAIN | V25: m GEN | W25: m NOZ | X25: m STO | Y25: mass STO | Z25: r prod | AA25: Po | AB25: Po | AC25: Po | AD25: Po
C26: mm | D26: mm | E26: mm | F26: mm | G26: mm | H26: mm2 | I26: m2 | J26: mm2 | M26: MPa (abs) | N26: mm/s. | P26: mm/s. | Q26: sec. | R26: mm3 | S26: m3 | T26: m3 | U26: kg. | V26: kg/s | W26: kg/s | X26: kg/s | Y26: kg | Z26: kg/m3 | AA26: Pa (abs) | AB26: Mpa (abs) | AC26: Mpa (gage) | AD26: psig
B28: 0 | C28: 0 | D28: =two -> 24.5 | E28: =dio -> 20 | F28: =do -> 69 | G28: =lgo -> 460 | H28: =PI()/4*(dto+erate*(two-D28)/two)^2 -> 221.47276 | I28: =H28/1000^2 -> 0.00022147276 | J28: =PI()/4*dc^2-PI()/4*(F28^2-E28^2) -> 992.74328 | K28: =J28/H28 -> 4.4824623 | L28: =IF((gstar-K28)<0,0,gstar-K28) -> 1.5175377 | M28: 0.101 | N28: =IF(fueltype=1,VLOOKUP($M28,kndxbn_,4),IF(fueltype=2,VLOOKUP($M28,knsobn_,4),IF(fueltype=3,VLOOKUP($M28,knsbcobn_,4),IF(fueltype=4,VLOOKUP($M28,knsubn_,4),IF(fueltype=5,am_1,IF(fueltype=6,am_0,IF(fueltype=7,am_3,am_4))))))) -> 8.875445 | O28: =IF(fueltype=1,VLOOKUP($M28,kndxbn_,5),IF(fueltype=2,VLOOKUP($M28,knsobn_,5),IF(fueltype=3,VLOOKUP($M28,knsbcobn_,5),IF(fueltype=4,VLOOKUP($M28,knsubn_,5),IF(fueltype=5,nm_1,IF(fueltype=6,an_0,IF(fueltype=7,nm_3,nm_4))))))) -> 0.6193 | P28: =(1+kv*L28)*N28*M28^O28 -> 2.145687 | Q28: 0 | R28: =PI()/4*(F28^2-E28^2)*G28 -> 1575555.8 | S28: =R28/1000^3 -> 0.0015755558 | T28: =(vc/1000^3-S28) -> 0.00050084055 | U28: =rhopgrain*R28/1000^2 -> 2.812446 | V28: 0 | W28: 0 | X28: =V28-W28 -> 0 | Y28: 0 | Z28: =Y28/T28 -> 0 | AA28: =Z28*rat*to+patm*1000000 -> 101000 | AB28: =AA28/1000000 -> 0.101 | AC28: =AB28-patm -> 0 | AD28: =AC28*1000000/6895 -> 0
B29: =1+B28 -> 1 | C29: =xincp+C28 -> 0.029376499 | D29: =(F29-E29)/2 -> 24.470624 | E29: =E28+ci*2*xincp -> 20.058753 | F29: =F28-osi*2*xincp -> 69 | G29: =G28-ei*n*2*xincp -> 459.76499 | H29: =PI()/4*(dto+erate*(two-D29)/two)^2 -> 221.47276 | I29: =H29/1000^2 -> 0.00022147276 | J29: =PI()/4*dc^2-PI()/4*(F29^2-E29^2) -> 994.59177 | K29: =J29/H29 -> 4.4908087 | L29: =IF((gstar-K29)<0,0,gstar-K29) -> 1.5091913 | M29: =AB28 -> 0.101 | N29: =IF(fueltype=1,VLOOKUP($M29,kndxbn_,4),IF(fueltype=2,VLOOKUP($M29,knsobn_,4),IF(fueltype=3,VLOOKUP($M29,knsbcobn_,4),IF(fueltype=4,VLOOKUP($M29,knsubn_,4),IF(fueltype=5,am_1,IF(fueltype=6,am_0,IF(fueltype=7,am_3,am_4))))))) -> 8.875445 | O29: =IF(fueltype=1,VLOOKUP($M29,kndxbn_,5),IF(fueltype=2,VLOOKUP($M29,knsobn_,5),IF(fueltype=3,VLOOKUP($M29,knsbcobn_,5),IF(fueltype=4,VLOOKUP($M29,knsubn_,5),IF(fueltype=5,nm_1,IF(fueltype=6,an_0,IF(fueltype=7,nm_3,nm_4))))))) -> 0.6193 | P29: =(1+kv*L29)*N29*M29^O29 -> 2.145687 | Q29: =xincp/P29+Q28 -> 0.013690953 | R29: =PI()/4*(F29^2-E29^2)*G29 -> 1573901 | S29: =R29/1000^3 -> 0.001573901 | T29: =(vc/1000^3-S29) -> 0.00050249537 | U29: =rhopgrain*R29/1000^2 -> 2.809492 | V29: =(U28-U29)/(Q29-Q28) -> 0.21575776 | W29: =IF(V29<AI29,IF(AB28>pbd,AI29,0),AI29) -> 0 | X29: =V29-W29 -> 0.21575776 | Y29: =IF((X29*(Q29-Q28)+Y28)<0,0,X29*(Q29-Q28)+Y28) -> 0.0029539294 | Z29: =Y29/T29 -> 5.8785205 | AA29: =Z29*rat*to+patm*1000000 -> 1972660.7 | AB29: =AA29/1000000 -> 1.9726607 | AC29: =AB29-patm -> 1.8716607 | AD29: =AC29*1000000/6895 -> 271.45187 | AI29: =($M29-patm)*1000000*$I29/SQRT(rat*to)*SQRT(k)*(2/(k+1))^((k+1)/2/(k-1)) -> 0
B30: =1+B29 -> 2 | C30: =xincp+C29 -> 0.058752998 | D30: =(F30-E30)/2 -> 24.441247 | E30: =E29+ci*2*xincp -> 20.117506 | F30: =F29-osi*2*xincp -> 69 | G30: =G29-ei*n*2*xincp -> 459.52998 | H30: =PI()/4*(dto+erate*(two-D30)/two)^2 -> 221.47276 | I30: =H30/1000^2 -> 0.00022147276 | J30: =PI()/4*dc^2-PI()/4*(F30^2-E30^2) -> 996.44568 | K30: =J30/H30 -> 4.4991795 | L30: =IF((gstar-K30)<0,0,gstar-K30) -> 1.5008205 | M30: =AB29 -> 1.9726607 | N30: =IF(fueltype=1,VLOOKUP($M30,kndxbn_,4),IF(fueltype=2,VLOOKUP($M30,knsobn_,4),IF(fueltype=3,VLOOKUP($M30,knsbcobn_,4),IF(fueltype=4,VLOOKUP($M30,knsubn_,4),IF(fueltype=5,am_1,IF(fueltype=6,am_0,IF(fueltype=7,am_3,am_4))))))) -> 7.5527844 | O30: =IF(fueltype=1,VLOOKUP($M30,kndxbn_,5),IF(fueltype=2,VLOOKUP($M30,knsobn_,5),IF(fueltype=3,VLOOKUP($M30,knsbcobn_,5),IF(fueltype=4,VLOOKUP($M30,knsubn_,5),IF(fueltype=5,nm_1,IF(fueltype=6,an_0,IF(fueltype=7,nm_3,nm_4))))))) -> -0.0087 | P30: =(1+kv*L30)*N30*M30^O30 -> 7.5082744 | Q30: =xincp/P30+Q29 -> 0.017603503 | R30: =PI()/4*(F30^2-E30^2)*G30 -> 1572244.6 | S30: =R30/1000^3 -> 0.0015722446 | T30: =(vc/1000^3-S30) -> 0.00050415181 | U30: =rhopgrain*R30/1000^2 -> 2.8065352 | V30: =(U29-U30)/(Q30-Q29) -> 0.75572868 | W30: =IF(V30<AI30,IF(AB29>pbd,AI30,0),AI30) -> 0.46629714 | X30: =V30-W30 -> 0.28943153 | Y30: =IF((X30*(Q30-Q29)+Y29)<0,0,X30*(Q30-Q29)+Y29) -> 0.0040863447 | Z30: =Y30/T30 -> 8.1053854 | AA30: =Z30*rat*to+patm*1000000 -> 2681671.6 | AB30: =AA30/1000000 -> 2.6816716 | AC30: =AB30-patm -> 2.5806716 | AD30: =AC30*1000000/6895 -> 374.28159 | AI30: =($M30-patm)*1000000*$I30/SQRT(rat*to)*SQRT(k)*(2/(k+1))^((k+1)/2/(k-1)) -> 0.46629714
B31: =1+B30 -> 3 | C31: =xincp+C30 -> 0.088129496 | D31: =(F31-E31)/2 -> 24.411871 | E31: =E30+ci*2*xincp -> 20.176259 | F31: =F30-osi*2*xincp -> 69 | G31: =G30-ei*n*2*xincp -> 459.29496 | H31: =PI()/4*(dto+erate*(two-D31)/two)^2 -> 221.47276 | I31: =H31/1000^2 -> 0.00022147276 | J31: =PI()/4*dc^2-PI()/4*(F31^2-E31^2) -> 998.30502 | K31: =J31/H31 -> 4.5075748 | L31: =IF((gstar-K31)<0,0,gstar-K31) -> 1.4924252 | M31: =AB30 -> 2.6816716 | N31: =IF(fueltype=1,VLOOKUP($M31,kndxbn_,4),IF(fueltype=2,VLOOKUP($M31,knsobn_,4),IF(fueltype=3,VLOOKUP($M31,knsbcobn_,4),IF(fueltype=4,VLOOKUP($M31,knsubn_,4),IF(fueltype=5,am_1,IF(fueltype=6,am_0,IF(fueltype=7,am_3,am_4))))))) -> 3.8408799 | O31: =IF(fueltype=1,VLOOKUP($M31,kndxbn_,5),IF(fueltype=2,VLOOKUP($M31,knsobn_,5),IF(fueltype=3,VLOOKUP($M31,knsbcobn_,5),IF(fueltype=4,VLOOKUP($M31,knsubn_,5),IF(fueltype=5,nm_1,IF(fueltype=6,an_0,IF(fueltype=7,nm_3,nm_4))))))) -> 0.6882 | P31: =(1+kv*L31)*N31*M31^O31 -> 7.5728518 | Q31: =xincp/P31+Q30 -> 0.021482689 | R31: =PI()/4*(F31^2-E31^2)*G31 -> 1570586.5 | S31: =R31/1000^3 -> 0.0015705865 | T31: =(vc/1000^3-S31) -> 0.00050580987 | U31: =rhopgrain*R31/1000^2 -> 2.8035755 | V31: =(U30-U31)/(Q31-Q30) -> 0.76297359 | W31: =IF(V31<AI31,IF(AB30>pbd,AI31,0),AI31) -> 0.64293694 | X31: =V31-W31 -> 0.12003664 | Y31: =IF((X31*(Q31-Q30)+Y30)<0,0,X31*(Q31-Q30)+Y30) -> 0.0045519891 | Z31: =Y31/T31 -> 8.9994075 | AA31: =Z31*rat*to+patm*1000000 -> 2966319.1 | AB31: =AA31/1000000 -> 2.9663191 | AC31: =AB31-patm -> 2.8653191 | AD31: =AC31*1000000/6895 -> 415.56477 | AI31: =($M31-patm)*1000000*$I31/SQRT(rat*to)*SQRT(k)*(2/(k+1))^((k+1)/2/(k-1)) -> 0.64293694
B32: =1+B31 -> 4 | C32: =xincp+C31 -> 0.117506 | D32: =(F32-E32)/2 -> 24.382494 | E32: =E31+ci*2*xincp -> 20.235012 | F32: =F31-osi*2*xincp -> 69 | G32: =G31-ei*n*2*xincp -> 459.05995 | H32: =PI()/4*(dto+erate*(two-D32)/two)^2 -> 221.47276 | I32: =H32/1000^2 -> 0.00022147276 | J32: =PI()/4*dc^2-PI()/4*(F32^2-E32^2) -> 1000.1698 | K32: =J32/H32 -> 4.5159946 | L32: =IF((gstar-K32)<0,0,gstar-K32) -> 1.4840054 | M32: =AB31 -> 2.9663191 | N32: =IF(fueltype=1,VLOOKUP($M32,kndxbn_,4),IF(fueltype=2,VLOOKUP($M32,knsobn_,4),IF(fueltype=3,VLOOKUP($M32,knsbcobn_,4),IF(fueltype=4,VLOOKUP($M32,knsubn_,4),IF(fueltype=5,am_1,IF(fueltype=6,am_0,IF(fueltype=7,am_3,am_4))))))) -> 3.8408799 | O32: =IF(fueltype=1,VLOOKUP($M32,kndxbn_,5),IF(fueltype=2,VLOOKUP($M32,knsobn_,5),IF(fueltype=3,VLOOKUP($M32,knsbcobn_,5),IF(fueltype=4,VLOOKUP($M32,knsubn_,5),IF(fueltype=5,nm_1,IF(fueltype=6,an_0,IF(fueltype=7,nm_3,nm_4))))))) -> 0.6882 | P32: =(1+kv*L32)*N32*M32^O32 -> 8.11729 | Q32: =xincp/P32+Q31 -> 0.025101692 | R32: =PI()/4*(F32^2-E32^2)*G32 -> 1568926.9 | S32: =R32/1000^3 -> 0.0015689269 | T32: =(vc/1000^3-S32) -> 0.00050746954 | U32: =rhopgrain*R32/1000^2 -> 2.8006129 | V32: =(U31-U32)/(Q32-Q31) -> 0.81862306 | W32: =IF(V32<AI32,IF(AB31>pbd,AI32,0),AI32) -> 0.71385274 | X32: =V32-W32 -> 0.10477032 | Y32: =IF((X32*(Q32-Q31)+Y31)<0,0,X32*(Q32-Q31)+Y31) -> 0.0049311533 | Z32: =Y32/T32 -> 9.7171413 | AA32: =Z32*rat*to+patm*1000000 -> 3194838.2 | AB32: =AA32/1000000 -> 3.1948382 | AC32: =AB32-patm -> 3.0938382 | AD32: =AC32*1000000/6895 -> 448.70749 | AI32: =($M32-patm)*1000000*$I32/SQRT(rat*to)*SQRT(k)*(2/(k+1))^((k+1)/2/(k-1)) -> 0.71385274
B33: =1+B32 -> 5 | C33: =xincp+C32 -> 0.14688249 | D33: =(F33-E33)/2 -> 24.353118 | E33: =E32+ci*2*xincp -> 20.293765 | F33: =F32-osi*2*xincp -> 69 | G33: =G32-ei*n*2*xincp -> 458.82494 | H33: =PI()/4*(dto+erate*(two-D33)/two)^2 -> 221.47276 | I33: =H33/1000^2 -> 0.00022147276 | J33: =PI()/4*dc^2-PI()/4*(F33^2-E33^2) -> 1002.04 | K33: =J33/H33 -> 4.5244389 | L33: =IF((gstar-K33)<0,0,gstar-K33) -> 1.4755611 | M33: =AB32 -> 3.1948382 | N33: =IF(fueltype=1,VLOOKUP($M33,kndxbn_,4),IF(fueltype=2,VLOOKUP($M33,knsobn_,4),IF(fueltype=3,VLOOKUP($M33,knsbcobn_,4),IF(fueltype=4,VLOOKUP($M33,knsubn_,4),IF(fueltype=5,am_1,IF(fueltype=6,am_0,IF(fueltype=7,am_3,am_4))))))) -> 3.8408799 | O33: =IF(fueltype=1,VLOOKUP($M33,kndxbn_,5),IF(fueltype=2,VLOOKUP($M33,knsobn_,5),IF(fueltype=3,VLOOKUP($M33,knsbcobn_,5),IF(fueltype=4,VLOOKUP($M33,knsubn_,5),IF(fueltype=5,nm_1,IF(fueltype=6,an_0,IF(fueltype=7,nm_3,nm_4))))))) -> 0.6882 | P33: =(1+kv*L33)*N33*M33^O33 -> 8.5426465 | Q33: =xincp/P33+Q32 -> 0.028540497 | R33: =PI()/4*(F33^2-E33^2)*G33 -> 1567265.6 | S33: =R33/1000^3 -> 0.0015672656 | T33: =(vc/1000^3-S33) -> 0.00050913083 | U33: =rhopgrain*R33/1000^2 -> 2.7976474 | V33: =(U32-U33)/(Q33-Q32) -> 0.86235642 | W33: =IF(V33<AI33,IF(AB32>pbd,AI33,0),AI33) -> 0.77078496 | X33: =V33-W33 -> 0.091571459 | Y33: =IF((X33*(Q33-Q32)+Y32)<0,0,X33*(Q33-Q32)+Y32) -> 0.0052460497 | Z33: =Y33/T33 -> 10.303933 | AA33: =Z33*rat*to+patm*1000000 -> 3381666.5 | AB33: =AA33/1000000 -> 3.3816665 | AC33: =AB33-patm -> 3.2806665 | AD33: =AC33*1000000/6895 -> 475.80369 | AI33: =($M33-patm)*1000000*$I33/SQRT(rat*to)*SQRT(k)*(2/(k+1))^((k+1)/2/(k-1)) -> 0.77078496
B34: =1+B33 -> 6 | C34: =xincp+C33 -> 0.17625899 | D34: =(F34-E34)/2 -> 24.323741 | E34: =E33+ci*2*xincp -> 20.352518 | F34: =F33-osi*2*xincp -> 69 | G34: =G33-ei*n*2*xincp -> 458.58993 | H34: =PI()/4*(dto+erate*(two-D34)/two)^2 -> 221.47276 | I34: =H34/1000^2 -> 0.00022147276 | J34: =PI()/4*dc^2-PI()/4*(F34^2-E34^2) -> 1003.9156 | K34: =J34/H34 -> 4.5329077 | L34: =IF((gstar-K34)<0,0,gstar-K34) -> 1.4670923 | M34: =AB33 -> 3.3816665 | N34: =IF(fueltype=1,VLOOKUP($M34,kndxbn_,4),IF(fueltype=2,VLOOKUP($M34,knsobn_,4),IF(fueltype=3,VLOOKUP($M34,knsbcobn_,4),IF(fueltype=4,VLOOKUP($M34,knsubn_,4),IF(fueltype=5,am_1,IF(fueltype=6,am_0,IF(fueltype=7,am_3,am_4))))))) -> 3.8408799 | O34: =IF(fueltype=1,VLOOKUP($M34,kndxbn_,5),IF(fueltype=2,VLOOKUP($M34,knsobn_,5),IF(fueltype=3,VLOOKUP($M34,knsbcobn_,5),IF(fueltype=4,VLOOKUP($M34,knsubn_,5),IF(fueltype=5,nm_1,IF(fueltype=6,an_0,IF(fueltype=7,nm_3,nm_4))))))) -> 0.6882 | P34: =(1+kv*L34)*N34*M34^O34 -> 8.8833858 | Q34: =xincp/P34+Q33 -> 0.031847401 | R34: =PI()/4*(F34^2-E34^2)*G34 -> 1565602.7 | S34: =R34/1000^3 -> 0.0015656027 | T34: =(vc/1000^3-S34) -> 0.00051079372 | U34: =rhopgrain*R34/1000^2 -> 2.7946791 | V34: =(U33-U34)/(Q34-Q33) -> 0.89762086 | W34: =IF(V34<AI34,IF(AB33>pbd,AI34,0),AI34) -> 0.81733053 | X34: =V34-W34 -> 0.080290334 | Y34: =IF((X34*(Q34-Q33)+Y33)<0,0,X34*(Q34-Q33)+Y33) -> 0.0055115621 | Z34: =Y34/T34 -> 10.790192 | AA34: =Z34*rat*to+patm*1000000 -> 3536486.3 | AB34: =AA34/1000000 -> 3.5364863 | AC34: =AB34-patm -> 3.4354863 | AD34: =AC34*1000000/6895 -> 498.25763 | AI34: =($M34-patm)*1000000*$I34/SQRT(rat*to)*SQRT(k)*(2/(k+1))^((k+1)/2/(k-1)) -> 0.81733053
B35: =1+B34 -> 7 | C35: =xincp+C34 -> 0.20563549 | D35: =(F35-E35)/2 -> 24.294365 | E35: =E34+ci*2*xincp -> 20.411271 | F35: =F34-osi*2*xincp -> 69 | G35: =G34-ei*n*2*xincp -> 458.35492 | H35: =PI()/4*(dto+erate*(two-D35)/two)^2 -> 221.47276 | I35: =H35/1000^2 -> 0.00022147276 | J35: =PI()/4*dc^2-PI()/4*(F35^2-E35^2) -> 1005.7966 | K35: =J35/H35 -> 4.5414009 | L35: =IF((gstar-K35)<0,0,gstar-K35) -> 1.4585991 | M35: =AB34 -> 3.5364863 | N35: =IF(fueltype=1,VLOOKUP($M35,kndxbn_,4),IF(fueltype=2,VLOOKUP($M35,knsobn_,4),IF(fueltype=3,VLOOKUP($M35,knsbcobn_,4),IF(fueltype=4,VLOOKUP($M35,knsubn_,4),IF(fueltype=5,am_1,IF(fueltype=6,am_0,IF(fueltype=7,am_3,am_4))))))) -> 3.8408799 | O35: =IF(fueltype=1,VLOOKUP($M35,kndxbn_,5),IF(fueltype=2,VLOOKUP($M35,knsobn_,5),IF(fueltype=3,VLOOKUP($M35,knsbcobn_,5),IF(fueltype=4,VLOOKUP($M35,knsubn_,5),IF(fueltype=5,nm_1,IF(fueltype=6,an_0,IF(fueltype=7,nm_3,nm_4))))))) -> 0.6882 | P35: =(1+kv*L35)*N35*M35^O35 -> 9.1613182 | Q35: =xincp/P35+Q34 -> 0.03505398 | R35: =PI()/4*(F35^2-E35^2)*G35 -> 1563938.2 | S35: =R35/1000^3 -> 0.0015639382 | T35: =(vc/1000^3-S35) -> 0.00051245821 | U35: =rhopgrain*R35/1000^2 -> 2.7917079 | V35: =(U34-U35)/(Q35-Q34) -> 0.92659729 | W35: =IF(V35<AI35,IF(AB34>pbd,AI35,0),AI35) -> 0.85590166 | X35: =V35-W35 -> 0.07069563 | Y35: =IF((X35*(Q35-Q34)+Y34)<0,0,X35*(Q35-Q34)+Y34) -> 0.0057382532 | Z35: =Y35/T35 -> 11.197505 | AA35: =Z35*rat*to+patm*1000000 -> 3666170.7 | AB35: =AA35/1000000 -> 3.6661707 | AC35: =AB35-patm -> 3.5651707 | AD35: =AC35*1000000/6895 -> 517.06609 | AI35: =($M35-patm)*1000000*$I35/SQRT(rat*to)*SQRT(k)*(2/(k+1))^((k+1)/2/(k-1)) -> 0.85590166
B36: =1+B35 -> 8 | C36: =xincp+C35 -> 0.23501199 | D36: =(F36-E36)/2 -> 24.264988 | E36: =E35+ci*2*xincp -> 20.470024 | F36: =F35-osi*2*xincp -> 69 | G36: =G35-ei*n*2*xincp -> 458.1199 | H36: =PI()/4*(dto+erate*(two-D36)/two)^2 -> 221.47276 | I36: =H36/1000^2 -> 0.00022147276 | J36: =PI()/4*dc^2-PI()/4*(F36^2-E36^2) -> 1007.683 | K36: =J36/H36 -> 4.5499187 | L36: =IF((gstar-K36)<0,0,gstar-K36) -> 1.4500813 | M36: =AB35 -> 3.6661707 | N36: =IF(fueltype=1,VLOOKUP($M36,kndxbn_,4),IF(fueltype=2,VLOOKUP($M36,knsobn_,4),IF(fueltype=3,VLOOKUP($M36,knsbcobn_,4),IF(fueltype=4,VLOOKUP($M36,knsubn_,4),IF(fueltype=5,am_1,IF(fueltype=6,am_0,IF(fueltype=7,am_3,am_4))))))) -> 3.8408799 | O36: =IF(fueltype=1,VLOOKUP($M36,kndxbn_,5),IF(fueltype=2,VLOOKUP($M36,knsobn_,5),IF(fueltype=3,VLOOKUP($M36,knsbcobn_,5),IF(fueltype=4,VLOOKUP($M36,knsubn_,5),IF(fueltype=5,nm_1,IF(fueltype=6,an_0,IF(fueltype=7,nm_3,nm_4))))))) -> 0.6882 | P36: =(1+kv*L36)*N36*M36^O36 -> 9.3912174 | Q36: =xincp/P36+Q35 -> 0.038182063 | R36: =PI()/4*(F36^2-E36^2)*G36 -> 1562272.1 | S36: =R36/1000^3 -> 0.0015622721 | T36: =(vc/1000^3-S36) -> 0.00051412431 | U36: =rhopgrain*R36/1000^2 -> 2.7887338 | V36: =(U35-U36)/(Q36-Q35) -> 0.95076283 | W36: =IF(V36<AI36,IF(AB35>pbd,AI36,0),AI36) -> 0.88821063 | X36: =V36-W36 -> 0.0625522 | Y36: =IF((X36*(Q36-Q35)+Y35)<0,0,X36*(Q36-Q35)+Y35) -> 0.0059339217 | Z36: =Y36/T36 -> 11.541803 | AA36: =Z36*rat*to+patm*1000000 -> 3775791.8 | AB36: =AA36/1000000 -> 3.7757918 | AC36: =AB36-patm -> 3.6747918 | AD36: =AC36*1000000/6895 -> 532.96473 | AI36: =($M36-patm)*1000000*$I36/SQRT(rat*to)*SQRT(k)*(2/(k+1))^((k+1)/2/(k-1)) -> 0.88821063
B37: =1+B36 -> 9 | C37: =xincp+C36 -> 0.26438849 | D37: =(F37-E37)/2 -> 24.235612 | E37: =E36+ci*2*xincp -> 20.528777 | F37: =F36-osi*2*xincp -> 69 | G37: =G36-ei*n*2*xincp -> 457.88489 | H37: =PI()/4*(dto+erate*(two-D37)/two)^2 -> 221.47276 | I37: =H37/1000^2 -> 0.00022147276 | J37: =PI()/4*dc^2-PI()/4*(F37^2-E37^2) -> 1009.5749 | K37: =J37/H37 -> 4.5584609 | L37: =IF((gstar-K37)<0,0,gstar-K37) -> 1.4415391 | M37: =AB36 -> 3.7757918 | N37: =IF(fueltype=1,VLOOKUP($M37,kndxbn_,4),IF(fueltype=2,VLOOKUP($M37,knsobn_,4),IF(fueltype=3,VLOOKUP($M37,knsbcobn_,4),IF(fueltype=4,VLOOKUP($M37,knsubn_,4),IF(fueltype=5,am_1,IF(fueltype=6,am_0,IF(fueltype=7,am_3,am_4))))))) -> 3.8408799 | O37: =IF(fueltype=1,VLOOKUP($M37,kndxbn_,5),IF(fueltype=2,VLOOKUP($M37,knsobn_,5),IF(fueltype=3,VLOOKUP($M37,knsbcobn_,5),IF(fueltype=4,VLOOKUP($M37,knsubn_,5),IF(fueltype=5,nm_1,IF(fueltype=6,an_0,IF(fueltype=7,nm_3,nm_4))))))) -> 0.6882 | P37: =(1+kv*L37)*N37*M37^O37 -> 9.5835776 | Q37: =xincp/P37+Q36 -> 0.041247358 | R37: =PI()/4*(F37^2-E37^2)*G37 -> 1560604.4 | S37: =R37/1000^3 -> 0.0015606044 | T37: =(vc/1000^3-S37) -> 0.000515792 | U37: =rhopgrain*R37/1000^2 -> 2.7857569 | V37: =(U36-U37)/(Q37-Q36) -> 0.97116677 | W37: =IF(V37<AI37,IF(AB36>pbd,AI37,0),AI37) -> 0.91552115 | X37: =V37-W37 -> 0.055645612 | Y37: =IF((X37*(Q37-Q36)+Y36)<0,0,X37*(Q37-Q36)+Y36) -> 0.0061044919 | Z37: =Y37/T37 -> 11.835181 | AA37: =Z37*rat*to+patm*1000000 -> 3869200.4 | AB37: =AA37/1000000 -> 3.8692004 | AC37: =AB37-patm -> 3.7682004 | AD37: =AC37*1000000/6895 -> 546.51202 | AI37: =($M37-patm)*1000000*$I37/SQRT(rat*to)*SQRT(k)*(2/(k+1))^((k+1)/2/(k-1)) -> 0.91552115
B38: =1+B37 -> 10 | C38: =xincp+C37 -> 0.29376499 | D38: =(F38-E38)/2 -> 24.206235 | E38: =E37+ci*2*xincp -> 20.58753 | F38: =F37-osi*2*xincp -> 69 | G38: =G37-ei*n*2*xincp -> 457.64988 | H38: =PI()/4*(dto+erate*(two-D38)/two)^2 -> 221.47276 | I38: =H38/1000^2 -> 0.00022147276 | J38: =PI()/4*dc^2-PI()/4*(F38^2-E38^2) -> 1011.4722 | K38: =J38/H38 -> 4.5670276 | L38: =IF((gstar-K38)<0,0,gstar-K38) -> 1.4329724 | M38: =AB37 -> 3.8692004 | N38: =IF(fueltype=1,VLOOKUP($M38,kndxbn_,4),IF(fueltype=2,VLOOKUP($M38,knsobn_,4),IF(fueltype=3,VLOOKUP($M38,knsbcobn_,4),IF(fueltype=4,VLOOKUP($M38,knsubn_,4),IF(fueltype=5,am_1,IF(fueltype=6,am_0,IF(fueltype=7,am_3,am_4))))))) -> 3.8408799 | O38: =IF(fueltype=1,VLOOKUP($M38,kndxbn_,5),IF(fueltype=2,VLOOKUP($M38,knsobn_,5),IF(fueltype=3,VLOOKUP($M38,knsbcobn_,5),IF(fueltype=4,VLOOKUP($M38,knsubn_,5),IF(fueltype=5,nm_1,IF(fueltype=6,an_0,IF(fueltype=7,nm_3,nm_4))))))) -> 0.6882 | P38: =(1+kv*L38)*N38*M38^O38 -> 9.7461178 | Q38: =xincp/P38+Q37 -> 0.044261533 | R38: =PI()/4*(F38^2-E38^2)*G38 -> 1558935.1 | S38: =R38/1000^3 -> 0.0015589351 | T38: =(vc/1000^3-S38) -> 0.00051746128 | U38: =rhopgrain*R38/1000^2 -> 2.7827771 | V38: =(U37-U38)/(Q38-Q37) -> 0.988581 | W38: =IF(V38<AI38,IF(AB37>pbd,AI38,0),AI38) -> 0.93879255 | X38: =V38-W38 -> 0.049788453 | Y38: =IF((X38*(Q38-Q37)+Y37)<0,0,X38*(Q38-Q37)+Y37) -> 0.006254563 | Z38: =Y38/T38 -> 12.087016 | AA38: =Z38*rat*to+patm*1000000 -> 3949382 | AB38: =AA38/1000000 -> 3.949382 | AC38: =AB38-patm -> 3.848382 | AD38: =AC38*1000000/6895 -> 558.14098 | AI38: =($M38-patm)*1000000*$I38/SQRT(rat*to)*SQRT(k)*(2/(k+1))^((k+1)/2/(k-1)) -> 0.93879255
B39: =1+B38 -> 11 | C39: =xincp+C38 -> 0.32314149 | D39: =(F39-E39)/2 -> 24.176859 | E39: =E38+ci*2*xincp -> 20.646283 | F39: =F38-osi*2*xincp -> 69 | G39: =G38-ei*n*2*xincp -> 457.41487 | H39: =PI()/4*(dto+erate*(two-D39)/two)^2 -> 221.47276 | I39: =H39/1000^2 -> 0.00022147276 | J39: =PI()/4*dc^2-PI()/4*(F39^2-E39^2) -> 1013.3749 | K39: =J39/H39 -> 4.5756188 | L39: =IF((gstar-K39)<0,0,gstar-K39) -> 1.4243812 | M39: =AB38 -> 3.949382 | N39: =IF(fueltype=1,VLOOKUP($M39,kndxbn_,4),IF(fueltype=2,VLOOKUP($M39,knsobn_,4),IF(fueltype=3,VLOOKUP($M39,knsbcobn_,4),IF(fueltype=4,VLOOKUP($M39,knsubn_,4),IF(fueltype=5,am_1,IF(fueltype=6,am_0,IF(fueltype=7,am_3,am_4))))))) -> 3.8408799 | O39: =IF(fueltype=1,VLOOKUP($M39,kndxbn_,5),IF(fueltype=2,VLOOKUP($M39,knsobn_,5),IF(fueltype=3,VLOOKUP($M39,knsbcobn_,5),IF(fueltype=4,VLOOKUP($M39,knsubn_,5),IF(fueltype=5,nm_1,IF(fueltype=6,an_0,IF(fueltype=7,nm_3,nm_4))))))) -> 0.6882 | P39: =(1+kv*L39)*N39*M39^O39 -> 9.884668 | Q39: =xincp/P39+Q38 -> 0.047233458 | R39: =PI()/4*(F39^2-E39^2)*G39 -> 1557264.2 | S39: =R39/1000^3 -> 0.0015572642 | T39: =(vc/1000^3-S39) -> 0.00051913216 | U39: =rhopgrain*R39/1000^2 -> 2.7797945 | V39: =(U38-U39)/(Q39-Q38) -> 1.0035887 | W39: =IF(V39<AI39,IF(AB38>pbd,AI39,0),AI39) -> 0.95876864 | X39: =V39-W39 -> 0.044820049 | Y39: =IF((X39*(Q39-Q38)+Y38)<0,0,X39*(Q39-Q38)+Y38) -> 0.0063877648 | Z39: =Y39/T39 -> 12.304699 | AA39: =Z39*rat*to+patm*1000000 -> 4018689.9 | AB39: =AA39/1000000 -> 4.0186899 | AC39: =AB39-patm -> 3.9176899 | AD39: =AC39*1000000/6895 -> 568.19288 | AI39: =($M39-patm)*1000000*$I39/SQRT(rat*to)*SQRT(k)*(2/(k+1))^((k+1)/2/(k-1)) -> 0.95876864
B40: =1+B39 -> 12 | C40: =xincp+C39 -> 0.35251799 | D40: =(F40-E40)/2 -> 24.147482 | E40: =E39+ci*2*xincp -> 20.705036 | F40: =F39-osi*2*xincp -> 69 | G40: =G39-ei*n*2*xincp -> 457.17986 | H40: =PI()/4*(dto+erate*(two-D40)/two)^2 -> 221.47276 | I40: =H40/1000^2 -> 0.00022147276 | J40: =PI()/4*dc^2-PI()/4*(F40^2-E40^2) -> 1015.283 | K40: =J40/H40 -> 4.5842345 | L40: =IF((gstar-K40)<0,0,gstar-K40) -> 1.4157655 | M40: =AB39 -> 4.0186899 | N40: =IF(fueltype=1,VLOOKUP($M40,kndxbn_,4),IF(fueltype=2,VLOOKUP($M40,knsobn_,4),IF(fueltype=3,VLOOKUP($M40,knsbcobn_,4),IF(fueltype=4,VLOOKUP($M40,knsubn_,4),IF(fueltype=5,am_1,IF(fueltype=6,am_0,IF(fueltype=7,am_3,am_4))))))) -> 3.8408799 | O40: =IF(fueltype=1,VLOOKUP($M40,kndxbn_,5),IF(fueltype=2,VLOOKUP($M40,knsobn_,5),IF(fueltype=3,VLOOKUP($M40,knsbcobn_,5),IF(fueltype=4,VLOOKUP($M40,knsubn_,5),IF(fueltype=5,nm_1,IF(fueltype=6,an_0,IF(fueltype=7,nm_3,nm_4))))))) -> 0.6882 | P40: =(1+kv*L40)*N40*M40^O40 -> 10.003724 | Q40: =xincp/P40+Q39 -> 0.050170015 | R40: =PI()/4*(F40^2-E40^2)*G40 -> 1555591.8 | S40: =R40/1000^3 -> 0.0015555918 | T40: =(vc/1000^3-S40) -> 0.00052080461 | U40: =rhopgrain*R40/1000^2 -> 2.7768091 | V40: =(U39-U40)/(Q40-Q39) -> 1.0166396 | W40: =IF(V40<AI40,IF(AB39>pbd,AI40,0),AI40) -> 0.9760357 | X40: =V40-W40 -> 0.040603929 | Y40: =IF((X40*(Q40-Q39)+Y39)<0,0,X40*(Q40-Q39)+Y39) -> 0.0065070006 | Z40: =Y40/T40 -> 12.49413 | AA40: =Z40*rat*to+patm*1000000 -> 4079002.9 | AB40: =AA40/1000000 -> 4.0790029 | AC40: =AB40-patm -> 3.9780029 | AD40: =AC40*1000000/6895 -> 576.94023 | AI40: =($M40-patm)*1000000*$I40/SQRT(rat*to)*SQRT(k)*(2/(k+1))^((k+1)/2/(k-1)) -> 0.9760357
... B862: =1+B861 -> 834 | C862: =xincp+C861 -> 24.5 | D862: =(F862-E862)/2 -> 1.8189894e-12 | E862: =E861+ci*2*xincp -> 69 | F862: =F861-osi*2*xincp -> 69 | G862: =G861-ei*n*2*xincp -> 264 | H862: =PI()/4*(dto+erate*(two-D862)/two)^2 -> 221.47276 | I862: =H862/1000^2 -> 0.00022147276 | J862: =PI()/4*dc^2-PI()/4*(F862^2-E862^2) -> 4417.8647 | K862: =J862/H862 -> 19.947666 | L862: =IF((gstar-K862)<0,0,gstar-K862) -> 0 | M862: =AB861 -> 4.8663105 | N862: =IF(fueltype=1,VLOOKUP($M862,kndxbn_,4),IF(fueltype=2,VLOOKUP($M862,knsobn_,4),IF(fueltype=3,VLOOKUP($M862,knsbcobn_,4),IF(fueltype=4,VLOOKUP($M862,knsubn_,4),IF(fueltype=5,am_1,IF(fueltype=6,am_0,IF(fueltype=7,am_3,am_4))))))) -> 3.8408799 | O862: =IF(fueltype=1,VLOOKUP($M862,kndxbn_,5),IF(fueltype=2,VLOOKUP($M862,knsobn_,5),IF(fueltype=3,VLOOKUP($M862,knsbcobn_,5),IF(fueltype=4,VLOOKUP($M862,knsubn_,5),IF(fueltype=5,nm_1,IF(fueltype=6,an_0,IF(fueltype=7,nm_3,nm_4))))))) -> 0.6882 | P862: =(1+kv*L862)*N862*M862^O862 -> 11.411997 | Q862: =xincp/P862+Q861 -> 1.9422242 | R862: =PI()/4*(F862^2-E862^2)*G862 -> 1.0409576e-07 | S862: =R862/1000^3 -> 1.0409576e-16 | T862: =(vc/1000^3-S862) -> 0.0020763964 | U862: =rhopgrain*R862/1000^2 -> 1.8581614e-13 | V862: =(U861-U862)/(Q862-Q861) -> 1.1663165 | W862: =IF(V862<AI862,IF(AB861>pbd,AI862,0),AI862) -> 1.1872081 | X862: =V862-W862 -> -0.0208916 | Y862: =IF((X862*(Q862-Q861)+Y861)<0,0,X862*(Q862-Q861)+Y861) -> 0.030998285 | Z862: =Y862/T862 -> 14.928886 | AA862: =Z862*rat*to+patm*1000000 -> 4854204.2 | AB862: =AA862/1000000 -> 4.8542042 | AC862: =AB862-patm -> 4.7532042 | AD862: =AC862*1000000/6895 -> 689.36972 | AI862: =($M862-patm)*1000000*$I862/SQRT(rat*to)*SQRT(k)*(2/(k+1))^((k+1)/2/(k-1)) -> 1.1872081
P863: =AVERAGE(P28:P862) -> 12.719867 | Q863: =Q862+tbinc -> 1.9439907 | AB863: =pbout*EXP(-rat*to*astarf*(Q863-tbout)/vc*1000000000/cstar) -> 4.5374274 | AC863: =AB863-patm -> 4.4364274 | AD863: =AC863*1000000/6895 -> 643.42674 | AI863: =($M863-patm)*1000000*$I863/SQRT(rat*to)*SQRT(k)*(2/(k+1))^((k+1)/2/(k-1)) -> 0
C864: twebo -twebf = | D864: =two-twebout -> 24.5 | Q864: =Q863+tbinc -> 1.9457572 | AB864: =pbout*EXP(-rat*to*astarf*(Q864-tbout)/vc*1000000000/cstar) -> 4.2413228 | AC864: =AB864-patm -> 4.1403228 | AD864: =AC864*1000000/6895 -> 600.48192 | AI864: =($M864-patm)*1000000*$I864/SQRT(rat*to)*SQRT(k)*(2/(k+1))^((k+1)/2/(k-1)) -> 0
D865: =two -> 24.5 | Q865: =Q864+tbinc -> 1.9475238 | AB865: =pbout*EXP(-rat*to*astarf*(Q865-tbout)/vc*1000000000/cstar) -> 3.9645415 | AC865: =AB865-patm -> 3.8635415 | AD865: =AC865*1000000/6895 -> 560.3396 | AI865: =($M865-patm)*1000000*$I865/SQRT(rat*to)*SQRT(k)*(2/(k+1))^((k+1)/2/(k-1)) -> 0
Q866: =Q865+tbinc -> 1.9492903 | AB866: =pbout*EXP(-rat*to*astarf*(Q866-tbout)/vc*1000000000/cstar) -> 3.7058225 | AC866: =AB866-patm -> 3.6048225 | AD866: =AC866*1000000/6895 -> 522.8169 | AI866: =($M866-patm)*1000000*$I866/SQRT(rat*to)*SQRT(k)*(2/(k+1))^((k+1)/2/(k-1)) -> 0
Q867: =Q866+tbinc -> 1.9510568 | AB867: =pbout*EXP(-rat*to*astarf*(Q867-tbout)/vc*1000000000/cstar) -> 3.463987 | AC867: =AB867-patm -> 3.362987 | AD867: =AC867*1000000/6895 -> 487.74286 | AI867: =($M867-patm)*1000000*$I867/SQRT(rat*to)*SQRT(k)*(2/(k+1))^((k+1)/2/(k-1)) -> 0
Q868: =Q867+tbinc -> 1.9528234 | AB868: =pbout*EXP(-rat*to*astarf*(Q868-tbout)/vc*1000000000/cstar) -> 3.2379333 | AC868: =AB868-patm -> 3.1369333 | AD868: =AC868*1000000/6895 -> 454.9577 | AI868: =($M868-patm)*1000000*$I868/SQRT(rat*to)*SQRT(k)*(2/(k+1))^((k+1)/2/(k-1)) -> 0
Q869: =Q868+tbinc -> 1.9545899 | AB869: =pbout*EXP(-rat*to*astarf*(Q869-tbout)/vc*1000000000/cstar) -> 3.0266315 | AC869: =AB869-patm -> 2.9256315 | AD869: =AC869*1000000/6895 -> 424.31204 | AI869: =($M869-patm)*1000000*$I869/SQRT(rat*to)*SQRT(k)*(2/(k+1))^((k+1)/2/(k-1)) -> 0
Q870: =Q869+tbinc -> 1.9563565 | AB870: =pbout*EXP(-rat*to*astarf*(Q870-tbout)/vc*1000000000/cstar) -> 2.8291188 | AC870: =AB870-patm -> 2.7281188 | AD870: =AC870*1000000/6895 -> 395.66625 | AI870: =($M870-patm)*1000000*$I870/SQRT(rat*to)*SQRT(k)*(2/(k+1))^((k+1)/2/(k-1)) -> 0
...

Sheet Performance
B1: Rocket Motor Performance
B3: k | C3: =k -> 1.1308 | E3: Ratio of specific heats, mixture
B4: h noz | C4: 0.85 | D4: =IF(etanoz>1,"Invalid","") | E4: Nozzle efficiency
B5: Ae/At | C5: 8 | E5: Nozzle expansion ratio (initial)
B6: Patm | C6: =patm -> 0.101 | D6: MPa | E6: Ambient pressure
B7: Ato | C7: =at -> 221.47276 | D7: mm2 | E7: Throat cross-section area (initial)
B8: Ae | C8: =exprat*at -> 1771.782 | D8: mm2 | E8: Nozzle exit cross-section area
B9: Meo | C9: 2.9545467 | D9: =exprat-1/me*((1+(k-1)/2*me^2)/(1+(k-1)/2))^((k+1)/2/(k-1)) -> -5.0599682e-06 | E9: Mach No. at nozzle exit (initial)
B10: Mef | C10: 2.9545467 | D10: =expratfinal-1/mef*((1+(k-1)/2*mef^2)/(1+(k-1)/2))^((k+1)/2/(k-1)) -> -5.0599682e-06 | E10: Mach No. at nozzle exit (final)
B11: De | C11: =SQRT(4*aexit/PI()) -> 47.496347 | D11: mm | E11: Nozzle exit diameter
B12: Ae/At opt | C12: =MAX(H28:H909) -> 9.7012504 | E12: Optimum Nozzle expansion ratio at Po max
B13: Ae/At opt | C13: =AVERAGE(H28:H909) -> 8.7850537 | E13: Avg. optimum nozzle expansion ratio
B14: w f | C14: =2*ravg*tbout/do -> 0.71608211 | E14: Web fraction
B15: CFmax | C15: =MAX(I28:I910) -> 1.3874894 | E15: Thrust coefficient, maximum
B16: F max | C16: =MAX(J28:J910) -> 1968.1156 | D16: N. | E16: Maximum thrust
B17: I t | C17: =itsum -> 3501.5343 | D17: N-sec. | E17: Total impulse
B18: Isp | C18: =itsum/9.806/mgrain -> 126.9645 | D18: sec. | E18: Specific impulse, delivered
B19: Class: | C19: =VLOOKUP(itsum,motorclass,2) -> L | E19: Motor classification
J21: F max = | K21: =fmax -> 1968.1156 | L21: N. | O21: F max = | P21: =fmax/4.4482 -> 442.45214 | Q21: lbf
G22: =D9 -> -5.0599682e-06 | J22: F avg = | K22: =itot/tthr -> 1728.9381 | L22: N. | O22: F avg = | P22: =itot/tthr/4.4482 -> 388.68264 | Q22: lbf
J23: t thrust = | K23: =tthr -> 2.0252514 | L23: sec. | O23: t thrust = | P23: =tthr -> 2.0252514 | Q23: sec.
C25: =Pressure!AB25 -> Po | D25: A* | E25: At | F25: Ae/At | G25: Pe | H25: Ae/At opt | I25: CF * hnoz | J25: F | K25: F | L25: t | M25: I t | N25: Me
C26: Pa (abs) | D26: m2 | E26: mm2 | G26: Pa (abs) | J26: N. | K26: lbf | L26: sec. | M26: N-sec.
C28: =Pressure!AB28*1000000 -> 101000 | D28: =Pressure!I28 -> 0.00022147276 | E28: =Pressure!H28 -> 221.47276 | F28: =aexit/E28 -> 8 | G28: =IF(C28/(1+(k-1)/2*N28^2)^(k/(k-1))<patm*1000000,patm*1000000,C28/(1+(k-1)/2*N28^2)^(k/(k-1))) -> 101000 | H28: 1 | I28: =etanoz -> 0.85 | J28: 0 | K28: =J28/4.4482 -> 0 | L28: =Pressure!Q28 -> 0 | M28: 0 | N28: =me -> 2.9545467
C29: =Pressure!AB29*1000000 -> 1972660.7 | D29: =Pressure!I29 -> 0.00022147276 | E29: =Pressure!H29 -> 221.47276 | F29: =aexit/E29 -> 8 | G29: =IF(C29/(1+(k-1)/2*N29^2)^(k/(k-1))<patm*1000000,patm*1000000,C29/(1+(k-1)/2*N29^2)^(k/(k-1))) -> 101000 | H29: =1/(((k+1)/2)^(1/(k-1))*(patm*1000000/C29)^(1/k)*SQRT((k+1)/(k-1)*(1-(patm*1000000/C29)^((k-1)/k)))) -> 3.9196066 | I29: =etanoz*SQRT(2*k^2/(k-1)*(2/(k+1))^((k+1)/(k-1))*(1-(G29/C29)^((k-1)/k)))+(G29-patm*1000000)/C29*(aexit/E29) -> 1.210035 | J29: =I29*D29*C29 -> 528.65289 | K29: =J29/4.4482 -> 118.84647 | L29: =Pressure!Q29 -> 0.013690953 | M29: =(J29+J28)/2*(L29-L28) -> 3.6188808 | N29: =N28-1/834*(me-mef) -> 2.9545467
C30: =Pressure!AB30*1000000 -> 2681671.6 | D30: =Pressure!I30 -> 0.00022147276 | E30: =Pressure!H30 -> 221.47276 | F30: =aexit/E30 -> 8 | G30: =IF(C30/(1+(k-1)/2*N30^2)^(k/(k-1))<patm*1000000,patm*1000000,C30/(1+(k-1)/2*N30^2)^(k/(k-1))) -> 101000 | H30: =1/(((k+1)/2)^(1/(k-1))*(patm*1000000/C30)^(1/k)*SQRT((k+1)/(k-1)*(1-(patm*1000000/C30)^((k-1)/k)))) -> 4.9367953 | I30: =etanoz*SQRT(2*k^2/(k-1)*(2/(k+1))^((k+1)/(k-1))*(1-(G30/C30)^((k-1)/k)))+(G30-patm*1000000)/C30*(aexit/E30) -> 1.2604438 | J30: =I30*D30*C30 -> 748.59924 | K30: =J30/4.4482 -> 168.29262 | L30: =Pressure!Q30 -> 0.017603503 | M30: =(J30+J29)/2*(L30-L29) -> 2.4986564 | N30: =N29-1/834*(me-mef) -> 2.9545467
C31: =Pressure!AB31*1000000 -> 2966319.1 | D31: =Pressure!I31 -> 0.00022147276 | E31: =Pressure!H31 -> 221.47276 | F31: =aexit/E31 -> 8 | G31: =IF(C31/(1+(k-1)/2*N31^2)^(k/(k-1))<patm*1000000,patm*1000000,C31/(1+(k-1)/2*N31^2)^(k/(k-1))) -> 101000 | H31: =1/(((k+1)/2)^(1/(k-1))*(patm*1000000/C31)^(1/k)*SQRT((k+1)/(k-1)*(1-(patm*1000000/C31)^((k-1)/k)))) -> 5.3308389 | I31: =etanoz*SQRT(2*k^2/(k-1)*(2/(k+1))^((k+1)/(k-1))*(1-(G31/C31)^((k-1)/k)))+(G31-patm*1000000)/C31*(aexit/E31) -> 1.2761965 | J31: =I31*D31*C31 -> 838.40858 | K31: =J31/4.4482 -> 188.48266 | L31: =Pressure!Q31 -> 0.021482689 | M31: =(J31+J30)/2*(L31-L30) -> 3.0781491 | N31: =N30-1/834*(me-mef) -> 2.9545467
C32: =Pressure!AB32*1000000 -> 3194838.2 | D32: =Pressure!I32 -> 0.00022147276 | E32: =Pressure!H32 -> 221.47276 | F32: =aexit/E32 -> 8 | G32: =IF(C32/(1+(k-1)/2*N32^2)^(k/(k-1))<patm*1000000,patm*1000000,C32/(1+(k-1)/2*N32^2)^(k/(k-1))) -> 101000 | H32: =1/(((k+1)/2)^(1/(k-1))*(patm*1000000/C32)^(1/k)*SQRT((k+1)/(k-1)*(1-(patm*1000000/C32)^((k-1)/k)))) -> 5.6422564 | I32: =etanoz*SQRT(2*k^2/(k-1)*(2/(k+1))^((k+1)/(k-1))*(1-(G32/C32)^((k-1)/k)))+(G32-patm*1000000)/C32*(aexit/E32) -> 1.287547 | J32: =I32*D32*C32 -> 911.02916 | K32: =J32/4.4482 -> 204.8085 | L32: =Pressure!Q32 -> 0.025101692 | M32: =(J32+J31)/2*(L32-L31) -> 3.1656104 | N32: =N31-1/834*(me-mef) -> 2.9545467
C33: =Pressure!AB33*1000000 -> 3381666.5 | D33: =Pressure!I33 -> 0.00022147276 | E33: =Pressure!H33 -> 221.47276 | F33: =aexit/E33 -> 8 | G33: =IF(C33/(1+(k-1)/2*N33^2)^(k/(k-1))<patm*1000000,patm*1000000,C33/(1+(k-1)/2*N33^2)^(k/(k-1))) -> 101000 | H33: =1/(((k+1)/2)^(1/(k-1))*(patm*1000000/C33)^(1/k)*SQRT((k+1)/(k-1)*(1-(patm*1000000/C33)^((k-1)/k)))) -> 5.8938899 | I33: =etanoz*SQRT(2*k^2/(k-1)*(2/(k+1))^((k+1)/(k-1))*(1-(G33/C33)^((k-1)/k)))+(G33-patm*1000000)/C33*(aexit/E33) -> 1.296107 | J33: =I33*D33*C33 -> 970.71542 | K33: =J33/4.4482 -> 218.22657 | L33: =Pressure!Q33 -> 0.028540497 | M33: =(J33+J32)/2*(L33-L32) -> 3.2354767 | N33: =N32-1/834*(me-mef) -> 2.9545467
C34: =Pressure!AB34*1000000 -> 3536486.3 | D34: =Pressure!I34 -> 0.00022147276 | E34: =Pressure!H34 -> 221.47276 | F34: =aexit/E34 -> 8 | G34: =IF(C34/(1+(k-1)/2*N34^2)^(k/(k-1))<patm*1000000,patm*1000000,C34/(1+(k-1)/2*N34^2)^(k/(k-1))) -> 101000 | H34: =1/(((k+1)/2)^(1/(k-1))*(patm*1000000/C34)^(1/k)*SQRT((k+1)/(k-1)*(1-(patm*1000000/C34)^((k-1)/k)))) -> 6.100527 | I34: =etanoz*SQRT(2*k^2/(k-1)*(2/(k+1))^((k+1)/(k-1))*(1-(G34/C34)^((k-1)/k)))+(G34-patm*1000000)/C34*(aexit/E34) -> 1.3027706 | J34: =I34*D34*C34 -> 1020.376 | K34: =J34/4.4482 -> 229.39077 | L34: =Pressure!Q34 -> 0.031847401 | M34: =(J34+J33)/2*(L34-L33) -> 3.2921736 | N34: =N33-1/834*(me-mef) -> 2.9545467
C35: =Pressure!AB35*1000000 -> 3666170.7 | D35: =Pressure!I35 -> 0.00022147276 | E35: =Pressure!H35 -> 221.47276 | F35: =aexit/E35 -> 8 | G35: =IF(C35/(1+(k-1)/2*N35^2)^(k/(k-1))<patm*1000000,patm*1000000,C35/(1+(k-1)/2*N35^2)^(k/(k-1))) -> 101000 | H35: =1/(((k+1)/2)^(1/(k-1))*(patm*1000000/C35)^(1/k)*SQRT((k+1)/(k-1)*(1-(patm*1000000/C35)^((k-1)/k)))) -> 6.2723722 | I35: =etanoz*SQRT(2*k^2/(k-1)*(2/(k+1))^((k+1)/(k-1))*(1-(G35/C35)^((k-1)/k)))+(G35-patm*1000000)/C35*(aexit/E35) -> 1.3080821 | J35: =I35*D35*C35 -> 1062.1063 | K35: =J35/4.4482 -> 238.77217 | L35: =Pressure!Q35 -> 0.03505398 | M35: =(J35+J34)/2*(L35-L34) -> 3.3388231 | N35: =N34-1/834*(me-mef) -> 2.9545467
C36: =Pressure!AB36*1000000 -> 3775791.8 | D36: =Pressure!I36 -> 0.00022147276 | E36: =Pressure!H36 -> 221.47276 | F36: =aexit/E36 -> 8 | G36: =IF(C36/(1+(k-1)/2*N36^2)^(k/(k-1))<patm*1000000,patm*1000000,C36/(1+(k-1)/2*N36^2)^(k/(k-1))) -> 101000 | H36: =1/(((k+1)/2)^(1/(k-1))*(patm*1000000/C36)^(1/k)*SQRT((k+1)/(k-1)*(1-(patm*1000000/C36)^((k-1)/k)))) -> 6.4167862 | I36: =etanoz*SQRT(2*k^2/(k-1)*(2/(k+1))^((k+1)/(k-1))*(1-(G36/C36)^((k-1)/k)))+(G36-patm*1000000)/C36*(aexit/E36) -> 1.3123951 | J36: =I36*D36*C36 -> 1097.4707 | K36: =J36/4.4482 -> 246.72243 | L36: =Pressure!Q36 -> 0.038182063 | M36: =(J36+J35)/2*(L36-L35) -> 3.3776672 | N36: =N35-1/834*(me-mef) -> 2.9545467
C37: =Pressure!AB37*1000000 -> 3869200.4 | D37: =Pressure!I37 -> 0.00022147276 | E37: =Pressure!H37 -> 221.47276 | F37: =aexit/E37 -> 8 | G37: =IF(C37/(1+(k-1)/2*N37^2)^(k/(k-1))<patm*1000000,patm*1000000,C37/(1+(k-1)/2*N37^2)^(k/(k-1))) -> 101000 | H37: =1/(((k+1)/2)^(1/(k-1))*(patm*1000000/C37)^(1/k)*SQRT((k+1)/(k-1)*(1-(patm*1000000/C37)^((k-1)/k)))) -> 6.5392525 | I37: =etanoz*SQRT(2*k^2/(k-1)*(2/(k+1))^((k+1)/(k-1))*(1-(G37/C37)^((k-1)/k)))+(G37-patm*1000000)/C37*(aexit/E37) -> 1.3159506 | J37: =I37*D37*C37 -> 1127.6677 | K37: =J37/4.4482 -> 253.51101 | L37: =Pressure!Q37 -> 0.041247358 | M37: =(J37+J36)/2*(L37-L36) -> 3.4103536 | N37: =N36-1/834*(me-mef) -> 2.9545467
C38: =Pressure!AB38*1000000 -> 3949382 | D38: =Pressure!I38 -> 0.00022147276 | E38: =Pressure!H38 -> 221.47276 | F38: =aexit/E38 -> 8 | G38: =IF(C38/(1+(k-1)/2*N38^2)^(k/(k-1))<patm*1000000,patm*1000000,C38/(1+(k-1)/2*N38^2)^(k/(k-1))) -> 101000 | H38: =1/(((k+1)/2)^(1/(k-1))*(patm*1000000/C38)^(1/k)*SQRT((k+1)/(k-1)*(1-(patm*1000000/C38)^((k-1)/k)))) -> 6.6439577 | I38: =etanoz*SQRT(2*k^2/(k-1)*(2/(k+1))^((k+1)/(k-1))*(1-(G38/C38)^((k-1)/k)))+(G38-patm*1000000)/C38*(aexit/E38) -> 1.3189198 | J38: =I38*D38*C38 -> 1153.6335 | K38: =J38/4.4482 -> 259.34838 | L38: =Pressure!Q38 -> 0.044261533 | M38: =(J38+J37)/2*(L38-L37) -> 3.4381198 | N38: =N37-1/834*(me-mef) -> 2.9545467
C39: =Pressure!AB39*1000000 -> 4018689.9 | D39: =Pressure!I39 -> 0.00022147276 | E39: =Pressure!H39 -> 221.47276 | F39: =aexit/E39 -> 8 | G39: =IF(C39/(1+(k-1)/2*N39^2)^(k/(k-1))<patm*1000000,patm*1000000,C39/(1+(k-1)/2*N39^2)^(k/(k-1))) -> 101000 | H39: =1/(((k+1)/2)^(1/(k-1))*(patm*1000000/C39)^(1/k)*SQRT((k+1)/(k-1)*(1-(patm*1000000/C39)^((k-1)/k)))) -> 6.7341589 | I39: =etanoz*SQRT(2*k^2/(k-1)*(2/(k+1))^((k+1)/(k-1))*(1-(G39/C39)^((k-1)/k)))+(G39-patm*1000000)/C39*(aexit/E39) -> 1.3214274 | J39: =I39*D39*C39 -> 1176.1105 | K39: =J39/4.4482 -> 264.40144 | L39: =Pressure!Q39 -> 0.047233458 | M39: =(J39+J38)/2*(L39-L38) -> 3.461913 | N39: =N38-1/834*(me-mef) -> 2.9545467
C40: =Pressure!AB40*1000000 -> 4079002.9 | D40: =Pressure!I40 -> 0.00022147276 | E40: =Pressure!H40 -> 221.47276 | F40: =aexit/E40 -> 8 | G40: =IF(C40/(1+(k-1)/2*N40^2)^(k/(k-1))<patm*1000000,patm*1000000,C40/(1+(k-1)/2*N40^2)^(k/(k-1))) -> 101000 | H40: =1/(((k+1)/2)^(1/(k-1))*(patm*1000000/C40)^(1/k)*SQRT((k+1)/(k-1)*(1-(patm*1000000/C40)^((k-1)/k)))) -> 6.8124287 | I40: =etanoz*SQRT(2*k^2/(k-1)*(2/(k+1))^((k+1)/(k-1))*(1-(G40/C40)^((k-1)/k)))+(G40-patm*1000000)/C40*(aexit/E40) -> 1.3235669 | J40: =I40*D40*C40 -> 1195.6944 | K40: =J40/4.4482 -> 268.80411 | L40: =Pressure!Q40 -> 0.050170015 | M40: =(J40+J39)/2*(L40-L39) -> 3.4824695 | N40: =N39-1/834*(me-mef) -> 2.9545467
... C862: =Pressure!AB862*1000000 -> 4854204.2 | D862: =Pressure!I862 -> 0.00022147276 | E862: =Pressure!H862 -> 221.47276 | F862: =aexit/E862 -> 8 | G862: =IF(C862/(1+(k-1)/2*N862^2)^(k/(k-1))<patm*1000000,patm*1000000,C862/(1+(k-1)/2*N862^2)^(k/(k-1))) -> 101000 | H862: =1/(((k+1)/2)^(1/(k-1))*(patm*1000000/C862)^(1/k)*SQRT((k+1)/(k-1)*(1-(patm*1000000/C862)^((k-1)/k)))) -> 7.8013387 | I862: =etanoz*SQRT(2*k^2/(k-1)*(2/(k+1))^((k+1)/(k-1))*(1-(G862/C862)^((k-1)/k)))+(G862-patm*1000000)/C862*(aexit/E862) -> 1.3480383 | J862: =I862*D862*C862 -> 1449.2409 | K862: =J862/4.4482 -> 325.8039 | L862: =Pressure!Q862 -> 1.9422242 | M862: =(J862+J861)/2*(L862-L861) -> 3.7357311 | N862: =N861-1/834*(me-mef) -> 2.9545467
C863: =Pressure!AB863*1000000 -> 4537427.4 | D863: =astarf -> 0.00022147276 | E863: =atfinal -> 221.47276 | G863: =IF(C863/(1+(k-1)/2*mef^2)^(k/(k-1))<patm*1000000,patm*1000000,C863/(1+(k-1)/2*mef^2)^(k/(k-1))) -> 101000 | H863: =1/(((k+1)/2)^(1/(k-1))*(patm*1000000/C863)^(1/k)*SQRT((k+1)/(k-1)*(1-(patm*1000000/C863)^((k-1)/k)))) -> 7.400881 | I863: =etanoz*SQRT(2*k^2/(k-1)*(2/(k+1))^((k+1)/(k-1))*(1-(G863/C863)^((k-1)/k)))+(G863-patm*1000000)/C863*(aexit/E863) -> 1.3386582 | J863: =I863*D863*C863 -> 1345.2398 | K863: =J863/4.4482 -> 302.4234 | L863: =Pressure!Q863 -> 1.9439907 | M863: =(J863+J862)/2*(L863-L862) -> 2.4682766
C864: =Pressure!AB864*1000000 -> 4241322.8 | D864: =astarf -> 0.00022147276 | E864: =atfinal -> 221.47276 | G864: =IF(C864/(1+(k-1)/2*mef^2)^(k/(k-1))<patm*1000000,patm*1000000,C864/(1+(k-1)/2*mef^2)^(k/(k-1))) -> 101000 | H864: =1/(((k+1)/2)^(1/(k-1))*(patm*1000000/C864)^(1/k)*SQRT((k+1)/(k-1)*(1-(patm*1000000/C864)^((k-1)/k)))) -> 7.0220664 | I864: =etanoz*SQRT(2*k^2/(k-1)*(2/(k+1))^((k+1)/(k-1))*(1-(G864/C864)^((k-1)/k)))+(G864-patm*1000000)/C864*(aexit/E864) -> 1.3291376 | J864: =I864*D864*C864 -> 1248.5087 | K864: =J864/4.4482 -> 280.67729 | L864: =Pressure!Q864 -> 1.9457572 | M864: =(J864+J863)/2*(L864-L863) -> 2.2909762
C865: =Pressure!AB865*1000000 -> 3964541.5 | D865: =astarf -> 0.00022147276 | E865: =atfinal -> 221.47276 | G865: =IF(C865/(1+(k-1)/2*mef^2)^(k/(k-1))<patm*1000000,patm*1000000,C865/(1+(k-1)/2*mef^2)^(k/(k-1))) -> 101000 | H865: =1/(((k+1)/2)^(1/(k-1))*(patm*1000000/C865)^(1/k)*SQRT((k+1)/(k-1)*(1-(patm*1000000/C865)^((k-1)/k)))) -> 6.663711 | I865: =etanoz*SQRT(2*k^2/(k-1)*(2/(k+1))^((k+1)/(k-1))*(1-(G865/C865)^((k-1)/k)))+(G865-patm*1000000)/C865*(aexit/E865) -> 1.3194729 | J865: =I865*D865*C865 -> 1158.5472 | K865: =J865/4.4482 -> 260.45305 | L865: =Pressure!Q865 -> 1.9475238 | M865: =(J865+J864)/2*(L865-L864) -> 2.1260766
...

Sheet Nozzle Design
B2: Nozzle Design
B5: beta | C5: 35 | D5: degrees | E5: Nozzle convergence half-angle
B6: alpha | C6: 12 | D6: degrees | E6: Nozzle divergence half-angle
F8: Reference worksheets:
B9: Dc | C9: =dc -> 75 | D9: mm | E9: Chamber inside diameter | F9: Data and Kn | Y9: =C6/180*PI() -> 0.20943951 | Z9: alpha
B10: Dt | C10: =dto -> 16.792494 | D10: mm | E10: Nozzle throat diameter | F10: Data and Kn | Y10: =C5/180*PI() -> 0.61086524 | Z10: beta
B11: De | C11: =Performance!C11 -> 47.496347 | D11: mm | E11: Nozzle exit diameter | F11: Performance
B12: De opt | C12: =SQRT(Performance!C13)*C10 -> 49.772267 | D12: mm | E12: Optimum nozzle exit diameter | F12: Performance | Y12: Graphing:
X13: Pt. | Y13: X | Z13: Y | AA13: -Y
B14: Lc | C14: =(dcplot-C10)/2/TAN(beta) -> 41.564466 | D14: mm | E14: Convergence length | X14: 1 | Y14: 0 | Z14: =dcplot/2 -> 37.5 | AA14: =-Z14 -> -37.5
B15: Ld | C15: =(C11-C10)/2/TAN(alpha) -> 72.225134 | D15: mm | E15: Divergence length | X15: 2 | Y15: =(C9-C10)/2/TAN(beta) -> 41.564466 | Z15: =C10/2 -> 8.3962472 | AA15: =-Z15 -> -8.3962472
B16: Lo | C16: =C15+C14 -> 113.7896 | D16: mm | E16: Overall length | X16: 3 | Y16: =((C11-C10)/2/TAN(alpha)+Y15) -> 113.7896 | Z16: =C11/2 -> 23.748173 | AA16: =-Z16 -> -23.748173
X17: 4 | Y17: =((C12-C10)/2/TAN(alpha)+Y15) -> 119.14328 | Z17: =C12/2 -> 24.886134 | AA17: =-Z17 -> -24.886134
X20: 1 | Y20: =Y14/dcplot -> 0 | Z20: =Z14/dcplot -> 0.5 | AA20: =AA14/dcplot -> -0.5
X21: 2 | Y21: =Y15/dcplot -> 0.55419289 | Z21: =Z15/dcplot -> 0.11194996 | AA21: =AA15/dcplot -> -0.11194996
X22: 3 | Y22: =Y16/dcplot -> 1.5171947 | Z22: =Z16/dcplot -> 0.31664231 | AA22: =AA16/dcplot -> -0.31664231
X23: 4 | Y23: =Y17/dcplot -> 1.5885771 | Z23: =Z17/dcplot -> 0.33181511 | AA23: =AA17/dcplot -> -0.33181511
Y24: =Y22 -> 1.5171947 | Z24: =Z22 -> 0.31664231
Y25: =Y22 -> 1.5171947 | Z25: =-Z22 -> -0.31664231
Y26: =Y23 -> 1.5885771 | Z26: =Z23 -> 0.33181511
Y27: =Y23 -> 1.5885771 | Z27: =-Z23 -> -0.33181511
Y28: =Y24 -> 1.5171947 | Z28: 1
Y29: =Y25 -> 1.5171947 | Z29: -1

Sheet Output
B2: Motor Output Data
B4: This page presents a summary of the key parameters of motor performance, which
B5: may be used in trajectory simulation software, such as SOAR.
B7: ='Data and Kn'!C6 -> Example Rocket Motor (L-Class)
B8: ='Data and Kn'!C7 -> utilizing KNDX propellant.
C9: Grain mass | D9: =mgrain -> 2.812446 | E9: kg.
D10: =D9/0.4536 -> 6.2002777 | E10: lb.
C11: Total impulse | D11: =itot -> 3501.5343 | E11: N-sec.
D12: =D11/4.448 -> 787.21544 | E12: lb-sec.
C13: Average thrust | D13: =Performance!K22 -> 1728.9381 | E13: N.
D14: =Performance!P22 -> 388.68264 | E14: lb.
C15: Thrust time | D15: =Performance!K23 -> 2.0252514 | E15: sec.
C16: Specific Impulse | D16: =Performance!C18 -> 126.9645 | E16: sec.
C17: Motor Classification | D17: =Performance!C19 -> L | E17: =Performance!K22 -> 1728.9381
B19: Thrust-time data [see note 1]
B20: Time step | C20: =N47 -> 0.095685442 | D20: sec. [see note2]
B22: Data pt. | C22: Time | D22: Thrust | E22: Thrust
C23: (sec.) | D23: (N.) | E23: (lb.)
B24: 1 | C24: =Performance!L28 -> 0 | D24: =Performance!J28 -> 0 | E24: =Performance!K28 -> 0
B25: =B24+1 -> 2 | C25: =Performance!L70 -> 0.1321674 | D25: =Performance!J70 -> 1401.9066 | E25: =Performance!K70 -> 315.16268 | N25: =C25-C24 -> 0.1321674
B26: =B25+1 -> 3 | C26: =Performance!L71 -> 0.13479998 | D26: =Performance!J71 -> 1405.8776 | E26: =Performance!K71 -> 316.05539 | N26: =C26-C25 -> 0.0026325837
B27: =B26+1 -> 4 | C27: =Performance!L112 -> 0.23909602 | D27: =Performance!J112 -> 1561.4628 | E27: =Performance!K112 -> 351.03251 | N27: =C27-C26 -> 0.10429604
B28: =B27+1 -> 5 | C28: =Performance!L154 -> 0.33958712 | D28: =Performance!J154 -> 1712.786 | E28: =Performance!K154 -> 385.05148 | N28: =C28-C27 -> 0.1004911
B29: =B28+1 -> 6 | C29: =Performance!L196 -> 0.434815 | D29: =Performance!J196 -> 1848.2423 | E29: =Performance!K196 -> 415.50341 | N29: =C29-C28 -> 0.095227879
B30: =B29+1 -> 7 | C30: =Performance!L238 -> 0.52855732 | D30: =Performance!J238 -> 1883.9413 | E30: =Performance!K238 -> 423.52892 | N30: =C30-C29 -> 0.093742324
B31: =B30+1 -> 8 | C31: =Performance!L280 -> 0.62251683 | D31: =Performance!J280 -> 1912.9352 | E31: =Performance!K280 -> 430.04704 | N31: =C31-C30 -> 0.09395951
B32: =B31+1 -> 9 | C32: =Performance!L322 -> 0.71664958 | D32: =Performance!J322 -> 1935.7953 | E32: =Performance!K322 -> 435.18622 | N32: =C32-C31 -> 0.09413275
B33: =B32+1 -> 10 | C33: =Performance!L364 -> 0.8109136 | D33: =Performance!J364 -> 1952.5592 | E33: =Performance!K364 -> 438.95491 | N33: =C33-C32 -> 0.094264016
B34: =B33+1 -> 11 | C34: =Performance!L406 -> 0.90526811 | D34: =Performance!J406 -> 1963.2542 | E34: =Performance!K406 -> 441.35925 | N34: =C34-C33 -> 0.094354511
B35: =B34+1 -> 12 | C35: =Performance!L448 -> 0.99967316 | D35: =Performance!J448 -> 1967.8981 | E35: =Performance!K448 -> 442.40323 | N35: =C35-C34 -> 0.094405052
B36: =B35+1 -> 13 | C36: =Performance!L490 -> 1.0940893 | D36: =Performance!J490 -> 1966.499 | E36: =Performance!K490 -> 442.08871 | N36: =C36-C35 -> 0.094416093
B37: =B36+1 -> 14 | C37: =Performance!L532 -> 1.188477 | D37: =Performance!J532 -> 1959.0561 | E37: =Performance!K532 -> 440.41547 | N37: =C37-C36 -> 0.094387737
B38: =B37+1 -> 15 | C38: =Performance!L574 -> 1.2827967 | D38: =Performance!J574 -> 1945.5592 | E38: =Performance!K574 -> 437.38123 | N38: =C38-C37 -> 0.094319744
B39: =B38+1 -> 16 | C39: =Performance!L616 -> 1.3770083 | D39: =Performance!J616 -> 1925.9886 | E39: =Performance!K616 -> 432.98156 | N39: =C39-C38 -> 0.09421152
B40: =B39+1 -> 17 | C40: =Performance!L658 -> 1.4710704 | D40: =Performance!J658 -> 1900.315 | E40: =Performance!K658 -> 427.20987 | N40: =C40-C39 -> 0.0940621
B41: =B40+1 -> 18 | C41: =Performance!L700 -> 1.5649405 | D41: =Performance!J700 -> 1868.4987 | E41: =Performance!K700 -> 420.05727 | N41: =C41-C40 -> 0.093870118
B42: =B41+1 -> 19 | C42: =Performance!L742 -> 1.6585742 | D42: =Performance!J742 -> 1830.4894 | E42: =Performance!K742 -> 411.51238 | N42: =C42-C41 -> 0.093633758
B43: =B42+1 -> 20 | C43: =Performance!L784 -> 1.7529401 | D43: =Performance!J784 -> 1743.1172 | E43: =Performance!K784 -> 391.87024 | N43: =C43-C42 -> 0.094365821
B44: =B43+1 -> 21 | C44: =Performance!L826 -> 1.8521554 | D44: =Performance!J826 -> 1590.6022 | E44: =Performance!K826 -> 357.58335 | N44: =C44-C43 -> 0.099215354
B45: =B44+1 -> 22 | C45: =Performance!L868 -> 1.9528234 | D45: =Performance!J868 -> 924.77255 | E45: =Performance!K868 -> 207.89815 | N45: =C45-C44 -> 0.10066797
...

Sheet Propellant data
B3: Propellant Data
B6: Propellant & combustion products physical/thermochemical properties
B7: Propellant type
C8: symb. | D8: units | E8: notes | F8: KNDX | G8: KNSB | H8: KNSU | I8: KNER | J8: KNMN | K8: KNFR | L8: KNPSB
B9: Grain mass density, ideal | C9: r p | D9: g/cm3 | E9: [1] | F9: 1.879 | G9: 1.841 | H9: 1.889 | I9: 1.82 | J9: 1.854 | K9: 1.942 | L9: 1.923
B10: Ratio of specific heats, mixture | C10: k | D10: - | E10: [2] | F10: 1.1308 | G10: 1.137 | H10: 1.133 | I10: 1.14 | J10: 1.1363 | K10: =ks_dx -> 1.1308 | L10: 1.163
B11: Effective molecular wt. | C11: M | D11: kg/kmol | E11: [3] | F11: 42.42 | G11: 39.9 | H11: 42.02 | I11: 38.58 | J11: 39.826 | K11: =m_dx -> 42.42 | L11: 36.39
B12: Chamber temperature | C12: To | D12: K | E12: [4] | F12: 1710 | G12: 1600 | H12: 1720 | I12: 1608 | J12: 1616 | K12: =to_dx -> 1710 | L12: 1858
C14: Notes: | D14: [1] | E14: Ref. ProPEP
D15: [2] | E15: For the gas-particle mixture.
D16: [3] | E16: Given by system mass divided by number of gas moles in system.
D17: [4] | E17: Adiabatic flame temperature.
C20: Additional Notes: | D20: KNDX = Potassium Nitrate/Dextrose, 65/35 O/F ratio
D21: KNSB = Potassium Nitrate/Sorbitol, 65/35 O/F ratio
D22: KNSU = Potassium Nitrate/Sucrose, 65/35 O/F ratio
D23: KNER = Potassium Nitrate/Erythritol, 65/35 O/F ratio
